Workbook

Sheet res for paper
D5: FP
D6: P | E6: Optimisitc | H6: Pessimistic | K6: Lazy
E7: A | F7: FR | G7: Time | H7: A | I7: FR | J7: Time | K7: A | L7: FR | M7: Time
D8: d11 | E8: =IF(ISNUMBER(FIND("±", results!B8)), LEFT(results!B8, FIND("±", results!B8) - 1), results!B8) -> 93.00 | F8: =IF(ISNUMBER(FIND("±", results!C8)), LEFT(results!C8, FIND("±", results!C8) - 1), results!C8) -> 2.02 | G8: =IF(ISNUMBER(FIND("±", results!D8)), LEFT(results!D8, FIND("±", results!D8) - 1), results!D8) -> 1.03 | H8: =IF(ISNUMBER(FIND("±", results!E8)), LEFT(results!E8, FIND("±", results!E8) - 1), results!E8) -> 140.72 | I8: =IF(ISNUMBER(FIND("±", results!F8)), LEFT(results!F8, FIND("±", results!F8) - 1), results!F8) -> 0.00 | J8: =IF(ISNUMBER(FIND("±", results!G8)), LEFT(results!G8, FIND("±", results!G8) - 1), results!G8) -> 3.13 | K8: =IF(ISNUMBER(FIND("±", results!H8)), LEFT(results!H8, FIND("±", results!H8) - 1), results!H8) -> 73.96 | L8: =IF(ISNUMBER(FIND("±", results!I8)), LEFT(results!I8, FIND("±", results!I8) - 1), results!I8) -> 0.10 | M8: =IF(ISNUMBER(FIND("±", results!J8)), LEFT(results!J8, FIND("±", results!J8) - 1), results!J8) -> 0.77
D9: d13 | E9: =IF(ISNUMBER(FIND("±", results!B9)), LEFT(results!B9, FIND("±", results!B9) - 1), results!B9) -> 109.82 | F9: =IF(ISNUMBER(FIND("±", results!C9)), LEFT(results!C9, FIND("±", results!C9) - 1), results!C9) -> 3.16 | G9: =IF(ISNUMBER(FIND("±", results!D9)), LEFT(results!D9, FIND("±", results!D9) - 1), results!D9) -> 1.94 | H9: =IF(ISNUMBER(FIND("±", results!E9)), LEFT(results!E9, FIND("±", results!E9) - 1), results!E9) -> 151.78 | I9: =IF(ISNUMBER(FIND("±", results!F9)), LEFT(results!F9, FIND("±", results!F9) - 1), results!F9) -> 0.00 | J9: =IF(ISNUMBER(FIND("±", results!G9)), LEFT(results!G9, FIND("±", results!G9) - 1), results!G9) -> 5.41 | K9: =IF(ISNUMBER(FIND("±", results!H9)), LEFT(results!H9, FIND("±", results!H9) - 1), results!H9) -> 88.24 | L9: =IF(ISNUMBER(FIND("±", results!I9)), LEFT(results!I9, FIND("±", results!I9) - 1), results!I9) -> 0.32 | M9: =IF(ISNUMBER(FIND("±", results!J9)), LEFT(results!J9, FIND("±", results!J9) - 1), results!J9) -> 1.33
D10: d15 | E10: =IF(ISNUMBER(FIND("±", results!B10)), LEFT(results!B10, FIND("±", results!B10) - 1), results!B10) -> 175.70 | F10: =IF(ISNUMBER(FIND("±", results!C10)), LEFT(results!C10, FIND("±", results!C10) - 1), results!C10) -> 3.40 | G10: =IF(ISNUMBER(FIND("±", results!D10)), LEFT(results!D10, FIND("±", results!D10) - 1), results!D10) -> 4.01 | H10: =IF(ISNUMBER(FIND("±", results!E10)), LEFT(results!E10, FIND("±", results!E10) - 1), results!E10) -> 247.32 | I10: =IF(ISNUMBER(FIND("±", results!F10)), LEFT(results!F10, FIND("±", results!F10) - 1), results!F10) -> 0.00 | J10: =IF(ISNUMBER(FIND("±", results!G10)), LEFT(results!G10, FIND("±", results!G10) - 1), results!G10) -> 11.45 | K10: =IF(ISNUMBER(FIND("±", results!H10)), LEFT(results!H10, FIND("±", results!H10) - 1), results!H10) -> 141.32 | L10: =IF(ISNUMBER(FIND("±", results!I10)), LEFT(results!I10, FIND("±", results!I10) - 1), results!I10) -> 0.14 | M10: =IF(ISNUMBER(FIND("±", results!J10)), LEFT(results!J10, FIND("±", results!J10) - 1), results!J10) -> 2.71
D11: c9-3 | E11: =IF(ISNUMBER(FIND("±", results!B11)), LEFT(results!B11, FIND("±", results!B11) - 1), results!B11) -> 694.66 | F11: =IF(ISNUMBER(FIND("±", results!C11)), LEFT(results!C11, FIND("±", results!C11) - 1), results!C11) -> 3.64 | G11: =IF(ISNUMBER(FIND("±", results!D11)), LEFT(results!D11, FIND("±", results!D11) - 1), results!D11) -> 47.25 | H11: =IF(ISNUMBER(FIND("±", results!E11)), LEFT(results!E11, FIND("±", results!E11) - 1), results!E11) -> 784.64 | I11: =IF(ISNUMBER(FIND("±", results!F11)), LEFT(results!F11, FIND("±", results!F11) - 1), results!F11) -> 0.00 | J11: =IF(ISNUMBER(FIND("±", results!G11)), LEFT(results!G11, FIND("±", results!G11) - 1), results!G11) -> 57.78 | K11: =IF(ISNUMBER(FIND("±", results!H11)), LEFT(results!H11, FIND("±", results!H11) - 1), results!H11) -> 738.94 | L11: =IF(ISNUMBER(FIND("±", results!I11)), LEFT(results!I11, FIND("±", results!I11) - 1), results!I11) -> 0.88 | M11: =IF(ISNUMBER(FIND("±", results!J11)), LEFT(results!J11, FIND("±", results!J11) - 1), results!J11) -> 49.58
D12: c11-1 | E12: =IF(ISNUMBER(FIND("±", results!B12)), LEFT(results!B12, FIND("±", results!B12) - 1), results!B12) -> 468.30 | F12: =IF(ISNUMBER(FIND("±", results!C12)), LEFT(results!C12, FIND("±", results!C12) - 1), results!C12) -> 1.24 | G12: =IF(ISNUMBER(FIND("±", results!D12)), LEFT(results!D12, FIND("±", results!D12) - 1), results!D12) -> 67.14 | H12: =IF(ISNUMBER(FIND("±", results!E12)), LEFT(results!E12, FIND("±", results!E12) - 1), results!E12) -> 491.42 | I12: =IF(ISNUMBER(FIND("±", results!F12)), LEFT(results!F12, FIND("±", results!F12) - 1), results!F12) -> 0.00 | J12: =IF(ISNUMBER(FIND("±", results!G12)), LEFT(results!G12, FIND("±", results!G12) - 1), results!G12) -> 79.38 | K12: =IF(ISNUMBER(FIND("±", results!H12)), LEFT(results!H12, FIND("±", results!H12) - 1), results!H12) -> 464.86 | L12: =IF(ISNUMBER(FIND("±", results!I12)), LEFT(results!I12, FIND("±", results!I12) - 1), results!I12) -> 0.44 | M12: =IF(ISNUMBER(FIND("±", results!J12)), LEFT(results!J12, FIND("±", results!J12) - 1), results!J12) -> 65.27
D13: c11-2 | E13: =IF(ISNUMBER(FIND("±", results!B13)), LEFT(results!B13, FIND("±", results!B13) - 1), results!B13) -> 888.42 | F13: =IF(ISNUMBER(FIND("±", results!C13)), LEFT(results!C13, FIND("±", results!C13) - 1), results!C13) -> 2.48 | G13: =IF(ISNUMBER(FIND("±", results!D13)), LEFT(results!D13, FIND("±", results!D13) - 1), results!D13) -> 149.29 | H13: =IF(ISNUMBER(FIND("±", results!E13)), LEFT(results!E13, FIND("±", results!E13) - 1), results!E13) -> 936.42 | I13: =IF(ISNUMBER(FIND("±", results!F13)), LEFT(results!F13, FIND("±", results!F13) - 1), results!F13) -> 0.00 | J13: =IF(ISNUMBER(FIND("±", results!G13)), LEFT(results!G13, FIND("±", results!G13) - 1), results!G13) -> 160.43 | K13: =IF(ISNUMBER(FIND("±", results!H13)), LEFT(results!H13, FIND("±", results!H13) - 1), results!H13) -> 956.64 | L13: =IF(ISNUMBER(FIND("±", results!I13)), LEFT(results!I13, FIND("±", results!I13) - 1), results!I13) -> 0.52 | M13: =IF(ISNUMBER(FIND("±", results!J13)), LEFT(results!J13, FIND("±", results!J13) - 1), results!J13) -> 157.74
D14: clog | E14: =IF(ISNUMBER(FIND("±", results!B13)), LEFT(results!B13, FIND("±", results!B13) - 1), results!B13) -> 888.42 | F14: =IF(ISNUMBER(FIND("±", results!C13)), LEFT(results!C13, FIND("±", results!C13) - 1), results!C13) -> 2.48 | G14: =IF(ISNUMBER(FIND("±", results!D13)), LEFT(results!D13, FIND("±", results!D13) - 1), results!D13) -> 149.29 | H14: =IF(ISNUMBER(FIND("±", results!E13)), LEFT(results!E13, FIND("±", results!E13) - 1), results!E13) -> 936.42 | I14: =IF(ISNUMBER(FIND("±", results!F13)), LEFT(results!F13, FIND("±", results!F13) - 1), results!F13) -> 0.00 | J14: =IF(ISNUMBER(FIND("±", results!G13)), LEFT(results!G13, FIND("±", results!G13) - 1), results!G13) -> 160.43 | K14: =IF(ISNUMBER(FIND("±", results!H13)), LEFT(results!H13, FIND("±", results!H13) - 1), results!H13) -> 956.64 | L14: =IF(ISNUMBER(FIND("±", results!I13)), LEFT(results!I13, FIND("±", results!I13) - 1), results!I13) -> 0.52 | M14: =IF(ISNUMBER(FIND("±", results!J13)), LEFT(results!J13, FIND("±", results!J13) - 1), results!J13) -> 157.74
D15: clog2 | E15: =IF(ISNUMBER(FIND("±", results!B15)), LEFT(results!B15, FIND("±", results!B15) - 1), results!B15) -> 0 | F15: =IF(ISNUMBER(FIND("±", results!C15)), LEFT(results!C15, FIND("±", results!C15) - 1), results!C15) -> 0 | G15: =IF(ISNUMBER(FIND("±", results!D15)), LEFT(results!D15, FIND("±", results!D15) - 1), results!D15) -> 0 | H15: =IF(ISNUMBER(FIND("±", results!E15)), LEFT(results!E15, FIND("±", results!E15) - 1), results!E15) -> 0 | I15: =IF(ISNUMBER(FIND("±", results!F15)), LEFT(results!F15, FIND("±", results!F15) - 1), results!F15) -> 0 | J15: =IF(ISNUMBER(FIND("±", results!G15)), LEFT(results!G15, FIND("±", results!G15) - 1), results!G15) -> 0 | K15: =IF(ISNUMBER(FIND("±", results!H15)), LEFT(results!H15, FIND("±", results!H15) - 1), results!H15) -> 0 | L15: =IF(ISNUMBER(FIND("±", results!I15)), LEFT(results!I15, FIND("±", results!I15) - 1), results!I15) -> 0 | M15: =IF(ISNUMBER(FIND("±", results!J15)), LEFT(results!J15, FIND("±", results!J15) - 1), results!J15) -> 0
D16: b7 | E16: =IF(ISNUMBER(FIND("±", results!B16)), LEFT(results!B16, FIND("±", results!B16) - 1), results!B16) -> 27.17 | F16: =IF(ISNUMBER(FIND("±", results!C16)), LEFT(results!C16, FIND("±", results!C16) - 1), results!C16) -> 11.42 | G16: =IF(ISNUMBER(FIND("±", results!D16)), LEFT(results!D16, FIND("±", results!D16) - 1), results!D16) -> 0.35 | H16: =IF(ISNUMBER(FIND("±", results!E16)), LEFT(results!E16, FIND("±", results!E16) - 1), results!E16) -> 23.54 | I16: =IF(ISNUMBER(FIND("±", results!F16)), LEFT(results!F16, FIND("±", results!F16) - 1), results!F16) -> 0.00 | J16: =IF(ISNUMBER(FIND("±", results!G16)), LEFT(results!G16, FIND("±", results!G16) - 1), results!G16) -> 0.35 | K16: =IF(ISNUMBER(FIND("±", results!H16)), LEFT(results!H16, FIND("±", results!H16) - 1), results!H16) -> 13.33 | L16: =IF(ISNUMBER(FIND("±", results!I16)), LEFT(results!I16, FIND("±", results!I16) - 1), results!I16) -> 2.88 | M16: =IF(ISNUMBER(FIND("±", results!J16)), LEFT(results!J16, FIND("±", results!J16) - 1), results!J16) -> 0.16
D17: b15
D18: u2 | E18: =IF(ISNUMBER(FIND("±", results!B18)), LEFT(results!B18, FIND("±", results!B18) - 1), results!B18) -> 184.12 | F18: =IF(ISNUMBER(FIND("±", results!C18)), LEFT(results!C18, FIND("±", results!C18) - 1), results!C18) -> 148.52 | G18: =IF(ISNUMBER(FIND("±", results!D18)), LEFT(results!D18, FIND("±", results!D18) - 1), results!D18) -> 3.46 | H18: =IF(ISNUMBER(FIND("±", results!E18)), LEFT(results!E18, FIND("±", results!E18) - 1), results!E18) -> 193.92 | I18: =IF(ISNUMBER(FIND("±", results!F18)), LEFT(results!F18, FIND("±", results!F18) - 1), results!F18) -> 0.00 | J18: =IF(ISNUMBER(FIND("±", results!G18)), LEFT(results!G18, FIND("±", results!G18) - 1), results!G18) -> 5.72 | K18: =IF(ISNUMBER(FIND("±", results!H18)), LEFT(results!H18, FIND("±", results!H18) - 1), results!H18) -> 61.66 | L18: =IF(ISNUMBER(FIND("±", results!I18)), LEFT(results!I18, FIND("±", results!I18) - 1), results!I18) -> 28.62 | M18: =IF(ISNUMBER(FIND("±", results!J18)), LEFT(results!J18, FIND("±", results!J18) - 1), results!J18) -> 0.51
D19: u3 | E19: =IF(ISNUMBER(FIND("±", results!B19)), LEFT(results!B19, FIND("±", results!B19) - 1), results!B19) -> 675.10 | F19: =IF(ISNUMBER(FIND("±", results!C19)), LEFT(results!C19, FIND("±", results!C19) - 1), results!C19) -> 604.26 | G19: =IF(ISNUMBER(FIND("±", results!D19)), LEFT(results!D19, FIND("±", results!D19) - 1), results!D19) -> 126.98 | H19: =IF(ISNUMBER(FIND("±", results!E19)), LEFT(results!E19, FIND("±", results!E19) - 1), results!E19) -> 634.76 | I19: =IF(ISNUMBER(FIND("±", results!F19)), LEFT(results!F19, FIND("±", results!F19) - 1), results!F19) -> 0.00 | J19: =IF(ISNUMBER(FIND("±", results!G19)), LEFT(results!G19, FIND("±", results!G19) - 1), results!G19) -> 194.14 | K19: =IF(ISNUMBER(FIND("±", results!H19)), LEFT(results!H19, FIND("±", results!H19) - 1), results!H19) -> 193.46 | L19: =IF(ISNUMBER(FIND("±", results!I19)), LEFT(results!I19, FIND("±", results!I19) - 1), results!I19) -> 118.76 | M19: =IF(ISNUMBER(FIND("±", results!J19)), LEFT(results!J19, FIND("±", results!J19) - 1), results!J19) -> 10.51
D20: w10 | E20: =IF(ISNUMBER(FIND("±", results!B20)), LEFT(results!B20, FIND("±", results!B20) - 1), results!B20) -> 111.70 | F20: =IF(ISNUMBER(FIND("±", results!C20)), LEFT(results!C20, FIND("±", results!C20) - 1), results!C20) -> 44.76 | G20: =IF(ISNUMBER(FIND("±", results!D20)), LEFT(results!D20, FIND("±", results!D20) - 1), results!D20) -> 4.24 | H20: =IF(ISNUMBER(FIND("±", results!E20)), LEFT(results!E20, FIND("±", results!E20) - 1), results!E20) -> 112.70 | I20: =IF(ISNUMBER(FIND("±", results!F20)), LEFT(results!F20, FIND("±", results!F20) - 1), results!F20) -> 0.00 | J20: =IF(ISNUMBER(FIND("±", results!G20)), LEFT(results!G20, FIND("±", results!G20) - 1), results!G20) -> 4.51 | K20: =IF(ISNUMBER(FIND("±", results!H20)), LEFT(results!H20, FIND("±", results!H20) - 1), results!H20) -> 96.44 | L20: =IF(ISNUMBER(FIND("±", results!I20)), LEFT(results!I20, FIND("±", results!I20) - 1), results!I20) -> 16.28 | M20: =IF(ISNUMBER(FIND("±", results!J20)), LEFT(results!J20, FIND("±", results!J20) - 1), results!J20) -> 1.79
D21: w15 | E21: =IF(ISNUMBER(FIND("±", results!B21)), LEFT(results!B21, FIND("±", results!B21) - 1), results!B21) -> 144.54 | F21: =IF(ISNUMBER(FIND("±", results!C21)), LEFT(results!C21, FIND("±", results!C21) - 1), results!C21) -> 62.50 | G21: =IF(ISNUMBER(FIND("±", results!D21)), LEFT(results!D21, FIND("±", results!D21) - 1), results!D21) -> 20.34 | H21: =IF(ISNUMBER(FIND("±", results!E21)), LEFT(results!E21, FIND("±", results!E21) - 1), results!E21) -> 145.54 | I21: =IF(ISNUMBER(FIND("±", results!F21)), LEFT(results!F21, FIND("±", results!F21) - 1), results!F21) -> 0.00 | J21: =IF(ISNUMBER(FIND("±", results!G21)), LEFT(results!G21, FIND("±", results!G21) - 1), results!G21) -> 23.43 | K21: =IF(ISNUMBER(FIND("±", results!H21)), LEFT(results!H21, FIND("±", results!H21) - 1), results!H21) -> 171.86 | L21: =IF(ISNUMBER(FIND("±", results!I21)), LEFT(results!I21, FIND("±", results!I21) - 1), results!I21) -> 35.50 | M21: =IF(ISNUMBER(FIND("±", results!J21)), LEFT(results!J21, FIND("±", results!J21) - 1), results!J21) -> 12.49
D25: FN | V25: FN
D26: P | E26: Optimisitc | I26: Pessimistic | M26: Lazy | Q26: MakeTrue | V26: P | W26: Optimisitc | AA26: Pessimistic | AE26: Lazy | AI26: MakeTrue
E27: Actions | F27: F-R | G27: Time | H27: SR | I27: Actions | J27: F-R | K27: Time | L27: SR | M27: Actions | N27: F-R | O27: Time | P27: SR | Q27: Actions | R27: F-R | S27: Time | T27: SR | W27: Actions | X27: F-R | Y27: Time | Z27: SR | AA27: Actions | AB27: F-R | AC27: Time | AD27: SR | AE27: Actions | AF27: F-R | AG27: Time | AH27: SR | AI27: Actions | AJ27: F-R | AK27: Time | AL27: SR
D28: d1 | E28: =IF(ISNUMBER(FIND("±", results!B28)), LEFT(results!B28, FIND("±", results!B28) - 1), results!B28) -> 94.34 | F28: =IF(ISNUMBER(FIND("±", results!C28)), LEFT(results!C28, FIND("±", results!C28) - 1), results!C28) -> 2.08 | G28: =IF(ISNUMBER(FIND("±", results!D28)), LEFT(results!D28, FIND("±", results!D28) - 1), results!D28) -> 0.77 | H28: =IF(ISNUMBER(FIND("±", results!E28)), LEFT(results!E28, FIND("±", results!E28) - 1), results!E28) -> 1 | I28: =IF(ISNUMBER(FIND("±", results!F28)), LEFT(results!F28, FIND("±", results!F28) - 1), results!F28) -> 136.28 | J28: =IF(ISNUMBER(FIND("±", results!G28)), LEFT(results!G28, FIND("±", results!G28) - 1), results!G28) -> 0.00 | K28: =IF(ISNUMBER(FIND("±", results!H28)), LEFT(results!H28, FIND("±", results!H28) - 1), results!H28) -> 2.20 | L28: =IF(ISNUMBER(FIND("±", results!I28)), LEFT(results!I28, FIND("±", results!I28) - 1), results!I28) -> 1 | ... T28: =IF(ISNUMBER(FIND("±", results!Q28)), LEFT(results!Q28, FIND("±", results!Q28) - 1), results!Q28) -> 1 | V28: d1 | W28: =IF(ISNUMBER(FIND("±", results!T28)), LEFT(results!T28, FIND("±", results!T28) - 1), results!T28) -> 88.27 | X28: =IF(ISNUMBER(FIND("±", results!U28)), LEFT(results!U28, FIND("±", results!U28) - 1), results!U28) -> 1.96 | Y28: =IF(ISNUMBER(FIND("±", results!V28)), LEFT(results!V28, FIND("±", results!V28) - 1), results!V28) -> 0.96 | Z28: =IF(ISNUMBER(FIND("±", results!W28)), LEFT(results!W28, FIND("±", results!W28) - 1), results!W28) -> 1 | AA28: =IF(ISNUMBER(FIND("±", results!X28)), LEFT(results!X28, FIND("±", results!X28) - 1), results!X28) -> 136.12 | AB28: =IF(ISNUMBER(FIND("±", results!Y28)), LEFT(results!Y28, FIND("±", results!Y28) - 1), results!Y28) -> 0.00 | AC28: =IF(ISNUMBER(FIND("±", results!Z28)), LEFT(results!Z28, FIND("±", results!Z28) - 1), results!Z28) -> 3.05 | AD28: =IF(ISNUMBER(FIND("±", results!AA28)), LEFT(results!AA28, FIND("±", results!AA28) - 1), results!AA28) -> 1 | ... AL28: =IF(ISNUMBER(FIND("±", results!AI28)), LEFT(results!AI28, FIND("±", results!AI28) - 1), results!AI28) -> 1
D29: d2 | E29: =IF(ISNUMBER(FIND("±", results!B29)), LEFT(results!B29, FIND("±", results!B29) - 1), results!B29) -> 107.81 | F29: =IF(ISNUMBER(FIND("±", results!C29)), LEFT(results!C29, FIND("±", results!C29) - 1), results!C29) -> 3.08 | G29: =IF(ISNUMBER(FIND("±", results!D29)), LEFT(results!D29, FIND("±", results!D29) - 1), results!D29) -> 1.41 | H29: =IF(ISNUMBER(FIND("±", results!E29)), LEFT(results!E29, FIND("±", results!E29) - 1), results!E29) -> 1 | I29: =IF(ISNUMBER(FIND("±", results!F29)), LEFT(results!F29, FIND("±", results!F29) - 1), results!F29) -> 144.46 | J29: =IF(ISNUMBER(FIND("±", results!G29)), LEFT(results!G29, FIND("±", results!G29) - 1), results!G29) -> 0.00 | K29: =IF(ISNUMBER(FIND("±", results!H29)), LEFT(results!H29, FIND("±", results!H29) - 1), results!H29) -> 3.84 | L29: =IF(ISNUMBER(FIND("±", results!I29)), LEFT(results!I29, FIND("±", results!I29) - 1), results!I29) -> 1 | ... T29: =IF(ISNUMBER(FIND("±", results!Q29)), LEFT(results!Q29, FIND("±", results!Q29) - 1), results!Q29) -> 0.96 | V29: d2 | W29: =IF(ISNUMBER(FIND("±", results!T29)), LEFT(results!T29, FIND("±", results!T29) - 1), results!T29) -> 107.91 | X29: =IF(ISNUMBER(FIND("±", results!U29)), LEFT(results!U29, FIND("±", results!U29) - 1), results!U29) -> 3.27 | Y29: =IF(ISNUMBER(FIND("±", results!V29)), LEFT(results!V29, FIND("±", results!V29) - 1), results!V29) -> 2.12 | Z29: =IF(ISNUMBER(FIND("±", results!W29)), LEFT(results!W29, FIND("±", results!W29) - 1), results!W29) -> 1 | AA29: =IF(ISNUMBER(FIND("±", results!X29)), LEFT(results!X29, FIND("±", results!X29) - 1), results!X29) -> 149.16 | AB29: =IF(ISNUMBER(FIND("±", results!Y29)), LEFT(results!Y29, FIND("±", results!Y29) - 1), results!Y29) -> 0.00 | AC29: =IF(ISNUMBER(FIND("±", results!Z29)), LEFT(results!Z29, FIND("±", results!Z29) - 1), results!Z29) -> 5.61 | AD29: =IF(ISNUMBER(FIND("±", results!AA29)), LEFT(results!AA29, FIND("±", results!AA29) - 1), results!AA29) -> 1 | ... AL29: =IF(ISNUMBER(FIND("±", results!AI29)), LEFT(results!AI29, FIND("±", results!AI29) - 1), results!AI29) -> 1
D30: d3 | E30: =IF(ISNUMBER(FIND("±", results!B30)), LEFT(results!B30, FIND("±", results!B30) - 1), results!B30) -> 174.45 | F30: =IF(ISNUMBER(FIND("±", results!C30)), LEFT(results!C30, FIND("±", results!C30) - 1), results!C30) -> 3.43 | G30: =IF(ISNUMBER(FIND("±", results!D30)), LEFT(results!D30, FIND("±", results!D30) - 1), results!D30) -> 4.15 | H30: =IF(ISNUMBER(FIND("±", results!E30)), LEFT(results!E30, FIND("±", results!E30) - 1), results!E30) -> 1 | I30: =IF(ISNUMBER(FIND("±", results!F30)), LEFT(results!F30, FIND("±", results!F30) - 1), results!F30) -> 236.70 | J30: =IF(ISNUMBER(FIND("±", results!G30)), LEFT(results!G30, FIND("±", results!G30) - 1), results!G30) -> 0.00 | K30: =IF(ISNUMBER(FIND("±", results!H30)), LEFT(results!H30, FIND("±", results!H30) - 1), results!H30) -> 10.74 | L30: =IF(ISNUMBER(FIND("±", results!I30)), LEFT(results!I30, FIND("±", results!I30) - 1), results!I30) -> 1 | ... T30: =IF(ISNUMBER(FIND("±", results!Q30)), LEFT(results!Q30, FIND("±", results!Q30) - 1), results!Q30) -> 0.94 | V30: d3 | W30: =IF(ISNUMBER(FIND("±", results!T30)), LEFT(results!T30, FIND("±", results!T30) - 1), results!T30) -> 162.73 | X30: =IF(ISNUMBER(FIND("±", results!U30)), LEFT(results!U30, FIND("±", results!U30) - 1), results!U30) -> 3.22 | Y30: =IF(ISNUMBER(FIND("±", results!V30)), LEFT(results!V30, FIND("±", results!V30) - 1), results!V30) -> 4.48 | Z30: =IF(ISNUMBER(FIND("±", results!W30)), LEFT(results!W30, FIND("±", results!W30) - 1), results!W30) -> 1 | AA30: =IF(ISNUMBER(FIND("±", results!X30)), LEFT(results!X30, FIND("±", results!X30) - 1), results!X30) -> 236.94 | AB30: =IF(ISNUMBER(FIND("±", results!Y30)), LEFT(results!Y30, FIND("±", results!Y30) - 1), results!Y30) -> 0.00 | AC30: =IF(ISNUMBER(FIND("±", results!Z30)), LEFT(results!Z30, FIND("±", results!Z30) - 1), results!Z30) -> 12.32 | AD30: =IF(ISNUMBER(FIND("±", results!AA30)), LEFT(results!AA30, FIND("±", results!AA30) - 1), results!AA30) -> 1 | ... AL30: =IF(ISNUMBER(FIND("±", results!AI30)), LEFT(results!AI30, FIND("±", results!AI30) - 1), results!AI30) -> 1
D31: cb1 | E31: =IF(ISNUMBER(FIND("±", results!B31)), LEFT(results!B31, FIND("±", results!B31) - 1), results!B31) -> 727.48 | F31: =IF(ISNUMBER(FIND("±", results!C31)), LEFT(results!C31, FIND("±", results!C31) - 1), results!C31) -> 3.52 | G31: =IF(ISNUMBER(FIND("±", results!D31)), LEFT(results!D31, FIND("±", results!D31) - 1), results!D31) -> 68.54 | H31: =IF(ISNUMBER(FIND("±", results!E31)), LEFT(results!E31, FIND("±", results!E31) - 1), results!E31) -> 1 | I31: =IF(ISNUMBER(FIND("±", results!F31)), LEFT(results!F31, FIND("±", results!F31) - 1), results!F31) -> 754.84 | J31: =IF(ISNUMBER(FIND("±", results!G31)), LEFT(results!G31, FIND("±", results!G31) - 1), results!G31) -> 0.00 | K31: =IF(ISNUMBER(FIND("±", results!H31)), LEFT(results!H31, FIND("±", results!H31) - 1), results!H31) -> 70.95 | L31: =IF(ISNUMBER(FIND("±", results!I31)), LEFT(results!I31, FIND("±", results!I31) - 1), results!I31) -> 1 | ... T31: =IF(ISNUMBER(FIND("±", results!Q31)), LEFT(results!Q31, FIND("±", results!Q31) - 1), results!Q31) -> 0.62 | V31: cb1 | W31: =IF(ISNUMBER(FIND("±", results!T31)), LEFT(results!T31, FIND("±", results!T31) - 1), results!T31) -> 701.68 | X31: =IF(ISNUMBER(FIND("±", results!U31)), LEFT(results!U31, FIND("±", results!U31) - 1), results!U31) -> 3.96 | Y31: =IF(ISNUMBER(FIND("±", results!V31)), LEFT(results!V31, FIND("±", results!V31) - 1), results!V31) -> 74.69 | Z31: =IF(ISNUMBER(FIND("±", results!W31)), LEFT(results!W31, FIND("±", results!W31) - 1), results!W31) -> 1.00 | AA31: =IF(ISNUMBER(FIND("±", results!X31)), LEFT(results!X31, FIND("±", results!X31) - 1), results!X31) -> 879.92 | AB31: =IF(ISNUMBER(FIND("±", results!Y31)), LEFT(results!Y31, FIND("±", results!Y31) - 1), results!Y31) -> 0.00 | AC31: =IF(ISNUMBER(FIND("±", results!Z31)), LEFT(results!Z31, FIND("±", results!Z31) - 1), results!Z31) -> 100.61 | AD31: =IF(ISNUMBER(FIND("±", results!AA31)), LEFT(results!AA31, FIND("±", results!AA31) - 1), results!AA31) -> 1.00 | ... AL31: =IF(ISNUMBER(FIND("±", results!AI31)), LEFT(results!AI31, FIND("±", results!AI31) - 1), results!AI31) -> 1
D32: cb2 | E32: =IF(ISNUMBER(FIND("±", results!B32)), LEFT(results!B32, FIND("±", results!B32) - 1), results!B32) -> 386.43 | F32: =IF(ISNUMBER(FIND("±", results!C32)), LEFT(results!C32, FIND("±", results!C32) - 1), results!C32) -> 1.14 | G32: =IF(ISNUMBER(FIND("±", results!D32)), LEFT(results!D32, FIND("±", results!D32) - 1), results!D32) -> 150.52 | H32: =IF(ISNUMBER(FIND("±", results!E32)), LEFT(results!E32, FIND("±", results!E32) - 1), results!E32) -> 1 | I32: =IF(ISNUMBER(FIND("±", results!F32)), LEFT(results!F32, FIND("±", results!F32) - 1), results!F32) -> 574.22 | J32: =IF(ISNUMBER(FIND("±", results!G32)), LEFT(results!G32, FIND("±", results!G32) - 1), results!G32) -> 0.00 | K32: =IF(ISNUMBER(FIND("±", results!H32)), LEFT(results!H32, FIND("±", results!H32) - 1), results!H32) -> 238.08 | L32: =IF(ISNUMBER(FIND("±", results!I32)), LEFT(results!I32, FIND("±", results!I32) - 1), results!I32) -> 1 | ... T32: =IF(ISNUMBER(FIND("±", results!Q32)), LEFT(results!Q32, FIND("±", results!Q32) - 1), results!Q32) -> 0.74 | V32: cb2 | W32: =IF(ISNUMBER(FIND("±", results!T32)), LEFT(results!T32, FIND("±", results!T32) - 1), results!T32) -> 551.14 | X32: =IF(ISNUMBER(FIND("±", results!U32)), LEFT(results!U32, FIND("±", results!U32) - 1), results!U32) -> 1.38 | Y32: =IF(ISNUMBER(FIND("±", results!V32)), LEFT(results!V32, FIND("±", results!V32) - 1), results!V32) -> 136.72 | Z32: =IF(ISNUMBER(FIND("±", results!W32)), LEFT(results!W32, FIND("±", results!W32) - 1), results!W32) -> 1.00 | AA32: =IF(ISNUMBER(FIND("±", results!X32)), LEFT(results!X32, FIND("±", results!X32) - 1), results!X32) -> 520.19 | AB32: =IF(ISNUMBER(FIND("±", results!Y32)), LEFT(results!Y32, FIND("±", results!Y32) - 1), results!Y32) -> 0.00 | AC32: =IF(ISNUMBER(FIND("±", results!Z32)), LEFT(results!Z32, FIND("±", results!Z32) - 1), results!Z32) -> 138.50 | AD32: =IF(ISNUMBER(FIND("±", results!AA32)), LEFT(results!AA32, FIND("±", results!AA32) - 1), results!AA32) -> 1.00 | ... AL32: =IF(ISNUMBER(FIND("±", results!AI32)), LEFT(results!AI32, FIND("±", results!AI32) - 1), results!AI32) -> 1.00
D33: cb3 | E33: =IF(ISNUMBER(FIND("±", results!B33)), LEFT(results!B33, FIND("±", results!B33) - 1), results!B33) -> 937.09 | F33: =IF(ISNUMBER(FIND("±", results!C33)), LEFT(results!C33, FIND("±", results!C33) - 1), results!C33) -> 2.38 | G33: =IF(ISNUMBER(FIND("±", results!D33)), LEFT(results!D33, FIND("±", results!D33) - 1), results!D33) -> 227.57 | H33: =IF(ISNUMBER(FIND("±", results!E33)), LEFT(results!E33, FIND("±", results!E33) - 1), results!E33) -> 1 | I33: =IF(ISNUMBER(FIND("±", results!F33)), LEFT(results!F33, FIND("±", results!F33) - 1), results!F33) -> 909.34 | J33: =IF(ISNUMBER(FIND("±", results!G33)), LEFT(results!G33, FIND("±", results!G33) - 1), results!G33) -> 0.00 | K33: =IF(ISNUMBER(FIND("±", results!H33)), LEFT(results!H33, FIND("±", results!H33) - 1), results!H33) -> 231.31 | L33: =IF(ISNUMBER(FIND("±", results!I33)), LEFT(results!I33, FIND("±", results!I33) - 1), results!I33) -> 1 | ... T33: =IF(ISNUMBER(FIND("±", results!Q33)), LEFT(results!Q33, FIND("±", results!Q33) - 1), results!Q33) -> 0.64 | V33: cb3
D34: c | E34: =IF(ISNUMBER(FIND("±", results!B34)), LEFT(results!B34, FIND("±", results!B34) - 1), results!B34) -> 138.46 | F34: =IF(ISNUMBER(FIND("±", results!C34)), LEFT(results!C34, FIND("±", results!C34) - 1), results!C34) -> 78.58 | G34: =IF(ISNUMBER(FIND("±", results!D34)), LEFT(results!D34, FIND("±", results!D34) - 1), results!D34) -> 11.73 | H34: =IF(ISNUMBER(FIND("±", results!E34)), LEFT(results!E34, FIND("±", results!E34) - 1), results!E34) -> 1 | I34: =IF(ISNUMBER(FIND("±", results!F34)), LEFT(results!F34, FIND("±", results!F34) - 1), results!F34) -> 184.30 | J34: =IF(ISNUMBER(FIND("±", results!G34)), LEFT(results!G34, FIND("±", results!G34) - 1), results!G34) -> 0.00 | K34: =IF(ISNUMBER(FIND("±", results!H34)), LEFT(results!H34, FIND("±", results!H34) - 1), results!H34) -> 24.75 | L34: =IF(ISNUMBER(FIND("±", results!I34)), LEFT(results!I34, FIND("±", results!I34) - 1), results!I34) -> 1 | ... T34: =IF(ISNUMBER(FIND("±", results!Q34)), LEFT(results!Q34, FIND("±", results!Q34) - 1), results!Q34) -> 1 | V34: c | W34: =IF(ISNUMBER(FIND("±", results!T34)), LEFT(results!T34, FIND("±", results!T34) - 1), results!T34) -> 135.08 | X34: =IF(ISNUMBER(FIND("±", results!U34)), LEFT(results!U34, FIND("±", results!U34) - 1), results!U34) -> 76.44 | Y34: =IF(ISNUMBER(FIND("±", results!V34)), LEFT(results!V34, FIND("±", results!V34) - 1), results!V34) -> 12.65 | Z34: =IF(ISNUMBER(FIND("±", results!W34)), LEFT(results!W34, FIND("±", results!W34) - 1), results!W34) -> 1 | AA34: =IF(ISNUMBER(FIND("±", results!X34)), LEFT(results!X34, FIND("±", results!X34) - 1), results!X34) -> 180.94 | AB34: =IF(ISNUMBER(FIND("±", results!Y34)), LEFT(results!Y34, FIND("±", results!Y34) - 1), results!Y34) -> 0.00 | AC34: =IF(ISNUMBER(FIND("±", results!Z34)), LEFT(results!Z34, FIND("±", results!Z34) - 1), results!Z34) -> 26.80 | AD34: =IF(ISNUMBER(FIND("±", results!AA34)), LEFT(results!AA34, FIND("±", results!AA34) - 1), results!AA34) -> 1 | ... AL34: =IF(ISNUMBER(FIND("±", results!AI34)), LEFT(results!AI34, FIND("±", results!AI34) - 1), results!AI34) -> 1
D35: c2
D36: b | E36: =IF(ISNUMBER(FIND("±", results!B35)), LEFT(results!B35, FIND("±", results!B35) - 1), results!B35) -> 28.34 | F36: =IF(ISNUMBER(FIND("±", results!C35)), LEFT(results!C35, FIND("±", results!C35) - 1), results!C35) -> 12.18 | G36: =IF(ISNUMBER(FIND("±", results!D35)), LEFT(results!D35, FIND("±", results!D35) - 1), results!D35) -> 0.46 | H36: =IF(ISNUMBER(FIND("±", results!E35)), LEFT(results!E35, FIND("±", results!E35) - 1), results!E35) -> 1 | I36: =IF(ISNUMBER(FIND("±", results!F35)), LEFT(results!F35, FIND("±", results!F35) - 1), results!F35) -> 24.16 | J36: =IF(ISNUMBER(FIND("±", results!G35)), LEFT(results!G35, FIND("±", results!G35) - 1), results!G35) -> 0.00 | K36: =IF(ISNUMBER(FIND("±", results!H35)), LEFT(results!H35, FIND("±", results!H35) - 1), results!H35) -> 0.44 | L36: =IF(ISNUMBER(FIND("±", results!I35)), LEFT(results!I35, FIND("±", results!I35) - 1), results!I35) -> 1 | ... T36: =IF(ISNUMBER(FIND("±", results!Q35)), LEFT(results!Q35, FIND("±", results!Q35) - 1), results!Q35) -> 1 | V36: b | W36: =IF(ISNUMBER(FIND("±", results!T35)), LEFT(results!T35, FIND("±", results!T35) - 1), results!T35) -> 29.60 | X36: =IF(ISNUMBER(FIND("±", results!U35)), LEFT(results!U35, FIND("±", results!U35) - 1), results!U35) -> 12.84 | Y36: =IF(ISNUMBER(FIND("±", results!V35)), LEFT(results!V35, FIND("±", results!V35) - 1), results!V35) -> 0.52 | Z36: =IF(ISNUMBER(FIND("±", results!W35)), LEFT(results!W35, FIND("±", results!W35) - 1), results!W35) -> 1 | AA36: =IF(ISNUMBER(FIND("±", results!X35)), LEFT(results!X35, FIND("±", results!X35) - 1), results!X35) -> 24.28 | AB36: =IF(ISNUMBER(FIND("±", results!Y35)), LEFT(results!Y35, FIND("±", results!Y35) - 1), results!Y35) -> 0.00 | AC36: =IF(ISNUMBER(FIND("±", results!Z35)), LEFT(results!Z35, FIND("±", results!Z35) - 1), results!Z35) -> 0.53 | AD36: =IF(ISNUMBER(FIND("±", results!AA35)), LEFT(results!AA35, FIND("±", results!AA35) - 1), results!AA35) -> 1 | ... AL36: =IF(ISNUMBER(FIND("±", results!AI35)), LEFT(results!AI35, FIND("±", results!AI35) - 1), results!AI35) -> 1
D37: b15
D38: u1 | E38: =IF(ISNUMBER(FIND("±", results!B36)), LEFT(results!B36, FIND("±", results!B36) - 1), results!B36) -> 185.42 | F38: =IF(ISNUMBER(FIND("±", results!C36)), LEFT(results!C36, FIND("±", results!C36) - 1), results!C36) -> 149.80 | G38: =IF(ISNUMBER(FIND("±", results!D36)), LEFT(results!D36, FIND("±", results!D36) - 1), results!D36) -> 4.41 | H38: =IF(ISNUMBER(FIND("±", results!E36)), LEFT(results!E36, FIND("±", results!E36) - 1), results!E36) -> 1 | I38: =IF(ISNUMBER(FIND("±", results!F36)), LEFT(results!F36, FIND("±", results!F36) - 1), results!F36) -> 197.68 | J38: =IF(ISNUMBER(FIND("±", results!G36)), LEFT(results!G36, FIND("±", results!G36) - 1), results!G36) -> 0.00 | K38: =IF(ISNUMBER(FIND("±", results!H36)), LEFT(results!H36, FIND("±", results!H36) - 1), results!H36) -> 6.53 | L38: =IF(ISNUMBER(FIND("±", results!I36)), LEFT(results!I36, FIND("±", results!I36) - 1), results!I36) -> 1 | ... T38: =IF(ISNUMBER(FIND("±", results!Q36)), LEFT(results!Q36, FIND("±", results!Q36) - 1), results!Q36) -> 1 | V38: u1 | W38: =IF(ISNUMBER(FIND("±", results!T36)), LEFT(results!T36, FIND("±", results!T36) - 1), results!T36) -> 166.86 | X38: =IF(ISNUMBER(FIND("±", results!U36)), LEFT(results!U36, FIND("±", results!U36) - 1), results!U36) -> 134.68 | Y38: =IF(ISNUMBER(FIND("±", results!V36)), LEFT(results!V36, FIND("±", results!V36) - 1), results!V36) -> 4.68 | Z38: =IF(ISNUMBER(FIND("±", results!W36)), LEFT(results!W36, FIND("±", results!W36) - 1), results!W36) -> 1 | AA38: =IF(ISNUMBER(FIND("±", results!X36)), LEFT(results!X36, FIND("±", results!X36) - 1), results!X36) -> 191.80 | AB38: =IF(ISNUMBER(FIND("±", results!Y36)), LEFT(results!Y36, FIND("±", results!Y36) - 1), results!Y36) -> 0.00 | AC38: =IF(ISNUMBER(FIND("±", results!Z36)), LEFT(results!Z36, FIND("±", results!Z36) - 1), results!Z36) -> 7.47 | AD38: =IF(ISNUMBER(FIND("±", results!AA36)), LEFT(results!AA36, FIND("±", results!AA36) - 1), results!AA36) -> 1 | ... AL38: =IF(ISNUMBER(FIND("±", results!AI36)), LEFT(results!AI36, FIND("±", results!AI36) - 1), results!AI36) -> 1
D39: u2 | E39: =IF(ISNUMBER(FIND("±", results!B37)), LEFT(results!B37, FIND("±", results!B37) - 1), results!B37) -> 653.36 | F39: =IF(ISNUMBER(FIND("±", results!C37)), LEFT(results!C37, FIND("±", results!C37) - 1), results!C37) -> 581.52 | G39: =IF(ISNUMBER(FIND("±", results!D37)), LEFT(results!D37, FIND("±", results!D37) - 1), results!D37) -> 143.15 | H39: =IF(ISNUMBER(FIND("±", results!E37)), LEFT(results!E37, FIND("±", results!E37) - 1), results!E37) -> 1 | I39: =IF(ISNUMBER(FIND("±", results!F37)), LEFT(results!F37, FIND("±", results!F37) - 1), results!F37) -> 749.72 | J39: =IF(ISNUMBER(FIND("±", results!G37)), LEFT(results!G37, FIND("±", results!G37) - 1), results!G37) -> 0.00 | K39: =IF(ISNUMBER(FIND("±", results!H37)), LEFT(results!H37, FIND("±", results!H37) - 1), results!H37) -> 262.53 | L39: =IF(ISNUMBER(FIND("±", results!I37)), LEFT(results!I37, FIND("±", results!I37) - 1), results!I37) -> 1 | ... T39: =IF(ISNUMBER(FIND("±", results!Q37)), LEFT(results!Q37, FIND("±", results!Q37) - 1), results!Q37) -> 1 | V39: u2 | W39: =IF(ISNUMBER(FIND("±", results!T37)), LEFT(results!T37, FIND("±", results!T37) - 1), results!T37) -> 641.08 | X39: =IF(ISNUMBER(FIND("±", results!U37)), LEFT(results!U37, FIND("±", results!U37) - 1), results!U37) -> 572.88 | Y39: =IF(ISNUMBER(FIND("±", results!V37)), LEFT(results!V37, FIND("±", results!V37) - 1), results!V37) -> 174.30 | Z39: =IF(ISNUMBER(FIND("±", results!W37)), LEFT(results!W37, FIND("±", results!W37) - 1), results!W37) -> 1.00 | AA39: =IF(ISNUMBER(FIND("±", results!X37)), LEFT(results!X37, FIND("±", results!X37) - 1), results!X37) -> 736.06 | AB39: =IF(ISNUMBER(FIND("±", results!Y37)), LEFT(results!Y37, FIND("±", results!Y37) - 1), results!Y37) -> 0.00 | AC39: =IF(ISNUMBER(FIND("±", results!Z37)), LEFT(results!Z37, FIND("±", results!Z37) - 1), results!Z37) -> 298.73 | AD39: =IF(ISNUMBER(FIND("±", results!AA37)), LEFT(results!AA37, FIND("±", results!AA37) - 1), results!AA37) -> 1.00 | ... AL39: =IF(ISNUMBER(FIND("±", results!AI37)), LEFT(results!AI37, FIND("±", results!AI37) - 1), results!AI37) -> 1.00
D40: w1 | E40: =IF(ISNUMBER(FIND("±", results!B38)), LEFT(results!B38, FIND("±", results!B38) - 1), results!B38) -> 91.67 | F40: =IF(ISNUMBER(FIND("±", results!C38)), LEFT(results!C38, FIND("±", results!C38) - 1), results!C38) -> 37.00 | G40: =IF(ISNUMBER(FIND("±", results!D38)), LEFT(results!D38, FIND("±", results!D38) - 1), results!D38) -> 3.57 | H40: =IF(ISNUMBER(FIND("±", results!E38)), LEFT(results!E38, FIND("±", results!E38) - 1), results!E38) -> 1 | I40: =IF(ISNUMBER(FIND("±", results!F38)), LEFT(results!F38, FIND("±", results!F38) - 1), results!F38) -> 92.78 | J40: =IF(ISNUMBER(FIND("±", results!G38)), LEFT(results!G38, FIND("±", results!G38) - 1), results!G38) -> 0.00 | K40: =IF(ISNUMBER(FIND("±", results!H38)), LEFT(results!H38, FIND("±", results!H38) - 1), results!H38) -> 3.76 | L40: =IF(ISNUMBER(FIND("±", results!I38)), LEFT(results!I38, FIND("±", results!I38) - 1), results!I38) -> 1 | ... T40: =IF(ISNUMBER(FIND("±", results!Q38)), LEFT(results!Q38, FIND("±", results!Q38) - 1), results!Q38) -> 0.9 | V40: w1
D41: w2 | E41: =IF(ISNUMBER(FIND("±", results!B39)), LEFT(results!B39, FIND("±", results!B39) - 1), results!B39) -> 181.33 | F41: =IF(ISNUMBER(FIND("±", results!C39)), LEFT(results!C39, FIND("±", results!C39) - 1), results!C39) -> 77.87 | G41: =IF(ISNUMBER(FIND("±", results!D39)), LEFT(results!D39, FIND("±", results!D39) - 1), results!D39) -> 32.05 | H41: =IF(ISNUMBER(FIND("±", results!E39)), LEFT(results!E39, FIND("±", results!E39) - 1), results!E39) -> 1 | I41: =IF(ISNUMBER(FIND("±", results!F39)), LEFT(results!F39, FIND("±", results!F39) - 1), results!F39) -> 182.33 | J41: =IF(ISNUMBER(FIND("±", results!G39)), LEFT(results!G39, FIND("±", results!G39) - 1), results!G39) -> 0.00 | K41: =IF(ISNUMBER(FIND("±", results!H39)), LEFT(results!H39, FIND("±", results!H39) - 1), results!H39) -> 31.89 | L41: =IF(ISNUMBER(FIND("±", results!I39)), LEFT(results!I39, FIND("±", results!I39) - 1), results!I39) -> 1 | ... T41: =IF(ISNUMBER(FIND("±", results!Q39)), LEFT(results!Q39, FIND("±", results!Q39) - 1), results!Q39) -> 1 | V41: w2
D45: FB
D46: P | E46: Optimisitc | I46: Lazy | M46: MakeTrue
E47: Actions | F47: F-R | G47: Time | H47: SR | I47: Actions | J47: F-R | K47: Time | L47: SR | M47: Actions | N47: F-R | O47: Time | P47: SR
D48: d1 | E48: =IF(ISNUMBER(FIND("±", results!B46)), LEFT(results!B46, FIND("±", results!B46) - 1), results!B46) -> 92.06 | F48: =IF(ISNUMBER(FIND("±", results!C46)), LEFT(results!C46, FIND("±", results!C46) - 1), results!C46) -> 2.06 | G48: =IF(ISNUMBER(FIND("±", results!D46)), LEFT(results!D46, FIND("±", results!D46) - 1), results!D46) -> 1.17 | H48: =IF(ISNUMBER(FIND("±", results!E46)), LEFT(results!E46, FIND("±", results!E46) - 1), results!E46) -> 1 | I48: =IF(ISNUMBER(FIND("±", results!F46)), LEFT(results!F46, FIND("±", results!F46) - 1), results!F46) -> 99.90 | J48: =IF(ISNUMBER(FIND("±", results!G46)), LEFT(results!G46, FIND("±", results!G46) - 1), results!G46) -> 0.39 | K48: =IF(ISNUMBER(FIND("±", results!H46)), LEFT(results!H46, FIND("±", results!H46) - 1), results!H46) -> 2.37 | L48: =IF(ISNUMBER(FIND("±", results!I46)), LEFT(results!I46, FIND("±", results!I46) - 1), results!I46) -> 1 | ... P48: =IF(ISNUMBER(FIND("±", results!M46)), LEFT(results!M46, FIND("±", results!M46) - 1), results!M46) -> 0.98
D49: d2 | E49: =IF(ISNUMBER(FIND("±", results!B47)), LEFT(results!B47, FIND("±", results!B47) - 1), results!B47) -> 105.29 | F49: =IF(ISNUMBER(FIND("±", results!C47)), LEFT(results!C47, FIND("±", results!C47) - 1), results!C47) -> 2.88 | G49: =IF(ISNUMBER(FIND("±", results!D47)), LEFT(results!D47, FIND("±", results!D47) - 1), results!D47) -> 2.29 | H49: =IF(ISNUMBER(FIND("±", results!E47)), LEFT(results!E47, FIND("±", results!E47) - 1), results!E47) -> 1 | I49: =IF(ISNUMBER(FIND("±", results!F47)), LEFT(results!F47, FIND("±", results!F47) - 1), results!F47) -> 107.55 | J49: =IF(ISNUMBER(FIND("±", results!G47)), LEFT(results!G47, FIND("±", results!G47) - 1), results!G47) -> 0.65 | K49: =IF(ISNUMBER(FIND("±", results!H47)), LEFT(results!H47, FIND("±", results!H47) - 1), results!H47) -> 3.96 | L49: =IF(ISNUMBER(FIND("±", results!I47)), LEFT(results!I47, FIND("±", results!I47) - 1), results!I47) -> 1 | ... P49: =IF(ISNUMBER(FIND("±", results!M47)), LEFT(results!M47, FIND("±", results!M47) - 1), results!M47) -> 0.98
D50: d3 | E50: =IF(ISNUMBER(FIND("±", results!B48)), LEFT(results!B48, FIND("±", results!B48) - 1), results!B48) -> 165.73 | F50: =IF(ISNUMBER(FIND("±", results!C48)), LEFT(results!C48, FIND("±", results!C48) - 1), results!C48) -> 3.08 | G50: =IF(ISNUMBER(FIND("±", results!D48)), LEFT(results!D48, FIND("±", results!D48) - 1), results!D48) -> 6.25 | H50: =IF(ISNUMBER(FIND("±", results!E48)), LEFT(results!E48, FIND("±", results!E48) - 1), results!E48) -> 1 | I50: =IF(ISNUMBER(FIND("±", results!F48)), LEFT(results!F48, FIND("±", results!F48) - 1), results!F48) -> 188.20 | J50: =IF(ISNUMBER(FIND("±", results!G48)), LEFT(results!G48, FIND("±", results!G48) - 1), results!G48) -> 0.86 | K50: =IF(ISNUMBER(FIND("±", results!H48)), LEFT(results!H48, FIND("±", results!H48) - 1), results!H48) -> 12.19 | L50: =IF(ISNUMBER(FIND("±", results!I48)), LEFT(results!I48, FIND("±", results!I48) - 1), results!I48) -> 1 | ... P50: =IF(ISNUMBER(FIND("±", results!M48)), LEFT(results!M48, FIND("±", results!M48) - 1), results!M48) -> 0.98
...

Sheet results
A5: FP | Q5: FP
A6: Problem | B6: Optimisitc | E6: Pessimistic | H6: Lazy | Q6: Problem | R6: Optimisitc | U6: Pessimistic | X6: Lazy
B7: Actions | C7: Failures | D7: Time | E7: Actions | F7: Failures | G7: Time | H7: Actions | I7: Failures | J7: Time | R7: Actions | S7: Failures | T7: Time | U7: Actions | V7: Failures | W7: Time | X7: Actions | Y7: Failures | Z7: Time
A8: doors-11 | B8: 93.00 ± 19.52 | C8: 2.02 ± 0.91 | D8: 1.03 ± 0.30 | E8: 140.72 ± 33.60 | F8: 0.00 ± 0.00 | G8: 3.13 ± 0.92 | H8: 73.96 ± 17.99 | I8: 0.10 ± 0.30 | J8: 0.77 ± 0.22 | Q8: doors-11 | R8: 89.84 ± 22.08 | S8: 2.00 ± 0.92 | T8: 1.10 ± 0.39 | U8: 131.80 ± 20.63 | V8: 0.00 ± 0.00 | W8: 3.35 ± 0.64 | X8: 73.62 ± 20.34 | Y8: 0.08 ± 0.27 | Z8: 0.87 ± 0.31
A9: doors-13 | B9: 109.82 ± 17.46 | C9: 3.16 ± 1.10 | D9: 1.94 ± 0.48 | E9: 151.78 ± 24.48 | F9: 0.00 ± 0.00 | G9: 5.41 ± 1.13 | H9: 88.24 ± 17.45 | I9: 0.32 ± 0.58 | J9: 1.33 ± 0.34 | Q9: doors-13 | R9: 110.86 ± 22.42 | S9: 3.12 ± 1.09 | T9: 2.09 ± 0.64 | U9: 145.08 ± 28.30 | V9: 0.00 ± 0.00 | W9: 5.40 ± 1.37 | X9: 88.46 ± 16.73 | Y9: 0.40 ± 0.57 | Z9: 1.65 ± 0.44
A10: doors-15 | B10: 175.70 ± 38.40 | C10: 3.40 ± 1.18 | D10: 4.01 ± 1.18 | E10: 247.32 ± 50.64 | F10: 0.00 ± 0.00 | G10: 11.45 ± 3.00 | H10: 141.32 ± 28.94 | I10: 0.14 ± 0.35 | J10: 2.71 ± 0.86 | Q10: doors-15 | R10: 155.62 ± 46.44 | S10: 2.94 ± 1.05 | T10: 6.40 ± 2.54 | U10: 230.16 ± 55.47 | V10: 0.00 ± 0.00 | W10: 17.37 ± 5.04 | X10: 134.76 ± 33.04 | Y10: 0.14 ± 0.40 | Z10: 6.52 ± 1.97
A11: colorballs-9-3 | B11: 694.66 ± 171.02 | C11: 3.64 ± 1.72 | D11: 47.25 ± 15.10 | E11: 784.64 ± 216.71 | F11: 0.00 ± 0.00 | G11: 57.78 ± 20.21 | H11: 738.94 ± 246.54 | I11: 0.88 ± 1.03 | J11: 49.58 ± 20.70 | Q11: colorballs-9-3 | R11: 747.32 ± 215.61 | S11: 3.94 ± 1.74 | T11: 83.91 ± 33.00 | U11: 800.86 ± 200.77 | V11: 0.00 ± 0.00 | W11: 92.27 ± 29.88 | X11: 726.44 ± 232.81 | Y11: 1.06 ± 0.99 | Z11: 79.75 ± 34.50
A12: colorballs-11-1 | B12: 468.30 ± 241.03 | C12: 1.24 ± 1.05 | D12: 67.14 ± 35.31 | E12: 491.42 ± 267.43 | F12: 0.00 ± 0.00 | G12: 79.38 ± 41.21 | H12: 464.86 ± 262.84 | I12: 0.44 ± 0.67 | J12: 65.27 ± 38.90 | Q12: colorballs-11-1 | R12: 419.46 ± 235.02 | S12: 1.30 ± 0.94 | T12: 89.76 ± 50.73 | U12: 428.26 ± 260.79 | V12: 0.00 ± 0.00 | W12: 99.91 ± 55.78 | X12: 489.72 ± 228.41 | Y12: 0.34 ± 0.59 | Z12: 99.00 ± 48.14
A13: colorballs-11-2 | B13: 888.42 ± 272.67 | C13: 2.48 ± 1.32 | D13: 149.29 ± 54.29 | E13: 936.42 ± 347.47 | F13: 0.00 ± 0.00 | G13: 160.43 ± 63.74 | H13: 956.64 ± 350.89 | I13: 0.52 ± 0.70 | J13: 157.74 ± 67.21 | Q13: colorballs-11-2 | R13: 838.54 ± 308.85 | S13: 2.72 ± 1.34 | T13: 227.58 ± 95.52 | U13: 876.26 ± 360.32 | V13: 0.00 ± 0.00 | W13: 241.60 ± 106.79 | X13: 884.16 ± 349.58 | Y13: 0.54 ± 0.70 | Z13: 228.66 ± 102.70
A14: cloghuge | B14: 143.70 ± 15.14 | C14: 80.14 ± 7.05 | D14: 11.16 ± 2.98 | E14: 189.48 ± 6.95 | F14: 0.00 ± 0.00 | G14: 23.12 ± 2.07 | H14: 79.60 ± 12.89 | I14: 16.16 ± 4.46 | J14: 3.69 ± 1.26
A15: cloghuge2 | Q15: cloghuge | R15: 134.04 ± 18.30 | S15: 75.40 ± 8.93 | T15: 11.62 ± 3.06 | U15: 182.90 ± 15.12 | V15: 0.00 ± 0.00 | W15: 27.10 ± 3.38 | X15: 76.52 ± 12.56 | Y15: 15.98 ± 4.35 | Z15: 4.84 ± 2.04
A16: blocks7 | B16: 27.17 ± 4.53 | C16: 11.42 ± 3.25 | D16: 0.35 ± 0.10 | E16: 23.54 ± 1.84 | F16: 0.00 ± 0.00 | G16: 0.35 ± 0.04 | H16: 13.33 ± 2.30 | I16: 2.88 ± 1.45 | J16: 0.16 ± 0.09 | Q16: blocks7 | R16: 27.96 ± 4.75 | S16: 11.86 ± 3.28 | T16: 0.53 ± 0.15 | U16: 23.62 ± 1.65 | V16: 0.00 ± 0.00 | W16: 0.51 ± 0.05 | X16: 13.26 ± 2.14 | Y16: 2.52 ± 1.15 | Z16: 0.20 ± 0.06
A17: blocks15
A18: unix2 | B18: 184.12 ± 62.39 | C18: 148.52 ± 49.04 | D18: 3.46 ± 1.42 | E18: 193.92 ± 68.22 | F18: 0.00 ± 0.00 | G18: 5.72 ± 2.03 | H18: 61.66 ± 26.09 | I18: 28.62 ± 11.56 | J18: 0.51 ± 0.23 | Q18: unix2 | R18: 161.00 ± 68.25 | S18: 130.78 ± 53.84 | T18: 4.20 ± 2.18 | U18: 173.68 ± 78.55 | V18: 0.00 ± 0.00 | W18: 6.84 ± 3.19 | X18: 58.20 ± 28.18 | Y18: 27.04 ± 12.28 | Z18: 0.83 ± 0.39
A19: unix3 | B19: 675.10 ± 281.13 | C19: 604.26 ± 250.70 | D19: 126.98 ± 73.03 | E19: 634.76 ± 316.77 | F19: 0.00 ± 0.00 | G19: 194.14 ± 108.19 | H19: 193.46 ± 91.05 | I19: 118.76 ± 52.85 | J19: 10.51 ± 5.79 | Q19: unix3 | R19: 635.88 ± 317.98 | S19: 566.43 ± 281.78 | T19: 171.00 ± 121.36 | U19: 765.49 ± 276.43 | V19: 0.00 ± 0.00 | W19: 342.86 ± 142.80 | X19: 198.94 ± 99.45 | Y19: 119.73 ± 56.20 | Z19: 16.07 ± 9.04
A20: wumpus10 | B20: 111.70 ± 64.96 | C20: 44.76 ± 25.29 | D20: 4.24 ± 2.83 | E20: 112.70 ± 64.96 | F20: 0.00 ± 0.00 | G20: 4.51 ± 2.94 | H20: 96.44 ± 24.15 | I20: 16.28 ± 4.82 | J20: 1.79 ± 0.48 | Q20: wumpus10 | R20: 93.06 ± 63.04 | S20: 37.82 ± 24.81 | T20: 4.08 ± 3.36 | U20: 94.06 ± 63.04 | V20: 0.00 ± 0.00 | W20: 4.83 ± 3.81 | X20: 80.50 ± 30.98 | Y20: 14.52 ± 5.86 | Z20: 2.37 ± 1.04
A21: wumpus15 | B21: 144.54 ± 114.33 | C21: 62.50 ± 47.82 | D21: 20.34 ± 19.99 | E21: 145.54 ± 114.33 | F21: 0.00 ± 0.00 | G21: 23.43 ± 21.41 | H21: 171.86 ± 55.02 | I21: 35.50 ± 10.54 | J21: 12.49 ± 4.65 | Q21: wumpus15 | R21: 164.88 ± 127.28 | S21: 71.02 ± 52.88 | T21: 32.44 ± 33.81 | U21: 165.88 ± 127.28 | V21: 0.00 ± 0.00 | W21: 38.18 ± 36.85 | X21: 161.24 ± 56.15 | Y21: 33.40 ± 11.49 | Z21: 23.67 ± 9.03
A25: FN | S25: FN
A26: Problem | B26: Optimisitc | F26: Pessimistic | J26: Lazy | N26: MakeTrue | S26: Problem | T26: Optimisitc | X26: Pessimistic | AB26: Lazy | AF26: MakeTrue
B27: Actions | C27: Failures | D27: Time | E27: SR | F27: Actions | G27: Failures | H27: Time | I27: SR | J27: Actions | K27: Failures | L27: Time | M27: SR | N27: Actions | O27: Failures | P27: Time | Q27: SR | T27: Actions | U27: Failures | V27: Time | W27: SR | X27: Actions | Y27: Failures | Z27: Time | AA27: SR | AB27: Actions | AC27: Failures | AD27: Time | AE27: SR | AF27: Actions | AG27: Failures | AH27: Time | AI27: SR
A28: doors-11 | B28: 94.34 ± 19.74 | C28: 2.08 ± 0.82 | D28: 0.77 ± 0.22 | E28: 1 | F28: 136.28 ± 32.19 | G28: 0.00 ± 0.00 | H28: 2.20 ± 0.54 | I28: 1 | J28: 101.78 ± 25.38 | K28: 0.00 ± 0.00 | L28: 1.60 ± 0.48 | M28: 1 | N28: 85.02 ± 18.97 | O28: 0.00 ± 0.00 | P28: 2.62 ± 0.64 | Q28: 1 | S28: doors-11 | T28: 88.27 ± 23.48 | U28: 1.96 ± 0.89 | V28: 0.96 ± 0.32 | W28: 1 | X28: 136.12 ± 29.87 | Y28: 0.00 ± 0.00 | Z28: 3.05 ± 0.72 | AA28: 1 | AB28: 94.42 ± 23.38 | AC28: 0.00 ± 0.00 | AD28: 1.50 ± 0.47 | AE28: 1 | AF28: 82.42 ± 17.56 | AG28: 0.00 ± 0.00 | AH28: 2.50 ± 0.66 | AI28: 1
A29: doors-13 | B29: 107.81 ± 25.86 | C29: 3.08 ± 1.17 | D29: 1.41 ± 0.48 | E29: 1 | F29: 144.46 ± 30.30 | G29: 0.00 ± 0.00 | H29: 3.84 ± 0.94 | I29: 1 | J29: 113.62 ± 24.75 | K29: 0.00 ± 0.00 | L29: 2.92 ± 0.83 | M29: 1 | N29: 103.58 ± 27.66 | O29: 0.00 ± 0.00 | P29: 4.87 ± 1.43 | Q29: 0.96 | S29: doors-13 | T29: 107.91 ± 19.95 | U29: 3.27 ± 1.12 | V29: 2.12 ± 0.51 | W29: 1 | X29: 149.16 ± 22.72 | Y29: 0.00 ± 0.00 | Z29: 5.61 ± 0.93 | AA29: 1 | AB29: 109.24 ± 25.21 | AC29: 0.00 ± 0.00 | AD29: 3.00 ± 0.89 | AE29: 1 | AF29: 98.87 ± 23.04 | AG29: 0.00 ± 0.00 | AH29: 5.32 ± 1.54 | AI29: 1
A30: doors-15 | B30: 174.45 ± 32.52 | C30: 3.43 ± 1.20 | D30: 4.15 ± 1.10 | E30: 1 | F30: 236.70 ± 61.19 | G30: 0.00 ± 0.00 | H30: 10.74 ± 3.38 | I30: 1 | J30: 188.04 ± 39.44 | K30: 0.00 ± 0.00 | L30: 7.95 ± 2.01 | M30: 1 | N30: 146.70 ± 48.84 | O30: 0.00 ± 0.00 | P30: 12.58 ± 5.70 | Q30: 0.94 | S30: doors-15 | T30: 162.73 ± 29.43 | U30: 3.22 ± 1.05 | V30: 4.48 ± 1.11 | W30: 1 | X30: 236.94 ± 56.29 | Y30: 0.00 ± 0.00 | Z30: 12.32 ± 4.28 | AA30: 1 | AB30: 175.88 ± 39.40 | AC30: 0.00 ± 0.00 | AD30: 7.21 ± 1.98 | AE30: 1 | AF30: 138.37 ± 40.40 | AG30: 0.00 ± 0.00 | AH30: 11.51 ± 5.19 | AI30: 1
A31: colorballs-9-3 | B31: 727.48 ± 243.78 | C31: 3.52 ± 1.46 | D31: 68.54 ± 27.30 | E31: 1 | F31: 754.84 ± 250.07 | G31: 0.00 ± 0.00 | H31: 70.95 ± 27.66 | I31: 1 | J31: 728.71 ± 230.72 | K31: 0.00 ± 0.00 | L31: 69.22 ± 26.67 | M31: 1 | N31: 723.35 ± 239.65 | O31: 0.00 ± 0.00 | P31: 75.43 ± 28.23 | Q31: 0.62 | S31: colorballs-9-3 | T31: 701.68 ± 167.25 | U31: 3.96 ± 1.28 | V31: 74.69 ± 22.55 | W31: 1.00 | X31: 879.92 ± 162.38 | Y31: 0.00 ± 0.00 | Z31: 100.61 ± 22.33 | AA31: 1.00 | AB31: 770.42 ± 207.47 | AC31: 0.00 ± 0.00 | AD31: 88.29 ± 27.67 | AE31: 1.00 | AF31: 685.90 ± 135.80 | AG31: 0.00 ± 0.00 | AH31: 75.65 ± 17.99 | AI31: 1
A32: colorballs-11-1 | B32: 386.43 ± 263.36 | C32: 1.14 ± 1.02 | D32: 150.52 ± 101.09 | E32: 1 | F32: 574.22 ± 248.23 | G32: 0.00 ± 0.00 | H32: 238.08 ± 93.07 | I32: 1 | J32: 398.49 ± 298.27 | K32: 0.00 ± 0.00 | L32: 169.22 ± 127.96 | M32: 1 | N32: 396.95 ± 297.32 | O32: 0.00 ± 0.00 | P32: 161.18 ± 120.62 | Q32: 0.74 | S32: colorballs-11-1 | T32: 551.14 ± 222.97 | U32: 1.38 ± 0.95 | V32: 136.72 ± 57.40 | W32: 1.00 | X32: 520.19 ± 192.05 | Y32: 0.00 ± 0.00 | Z32: 138.50 ± 45.88 | AA32: 1.00 | AB32: 462.81 ± 351.41 | AC32: 0.00 ± 0.00 | AD32: 133.48 ± 95.58 | AE32: 1.00 | AF32: 463.65 ± 308.59 | AG32: 0.00 ± 0.00 | AH32: 137.25 ± 82.38 | AI32: 1.00
A33: colorballs-11-2 | B33: 937.09 ± 273.39 | C33: 2.38 ± 1.45 | D33: 227.57 ± 73.91 | E33: 1 | F33: 909.34 ± 311.61 | G33: 0.00 ± 0.00 | H33: 231.31 ± 77.61 | I33: 1 | J33: 919.50 ± 381.52 | K33: 0.00 ± 0.00 | L33: 213.79 ± 94.50 | M33: 1 | N33: 830.06 ± 382.45 | O33: 0.00 ± 0.00 | P33: 192.95 ± 86.85 | Q33: 0.64 | S33: colorballs-11-2
A34: cloghuge | B34: 138.46 ± 17.85 | C34: 78.58 ± 8.72 | D34: 11.73 ± 2.46 | E34: 1 | F34: 184.30 ± 11.99 | G34: 0.00 ± 0.00 | H34: 24.75 ± 2.80 | I34: 1 | J34: 111.36 ± 42.55 | K34: 0.00 ± 0.00 | L34: 13.58 ± 9.12 | M34: 1 | N34: 73.88 ± 14.02 | O34: 0.00 ± 0.00 | P34: 6.13 ± 2.90 | Q34: 1 | S34: cloghuge | T34: 135.08 ± 16.73 | U34: 76.44 ± 9.70 | V34: 12.65 ± 2.64 | W34: 1 | X34: 180.94 ± 16.52 | Y34: 0.00 ± 0.00 | Z34: 26.80 ± 3.78 | AA34: 1 | AB34: 121.74 ± 39.70 | AC34: 0.00 ± 0.00 | AD34: 16.45 ± 8.35 | AE34: 1 | AF34: 76.20 ± 9.55 | AG34: 0.00 ± 0.00 | AH34: 7.09 ± 1.76 | AI34: 1
A35: blocks7 | B35: 28.34 ± 5.24 | C35: 12.18 ± 3.70 | D35: 0.46 ± 0.12 | E35: 1 | F35: 24.16 ± 1.94 | G35: 0.00 ± 0.00 | H35: 0.44 ± 0.04 | I35: 1 | J35: 10.60 ± 3.20 | K35: 0.00 ± 0.00 | L35: 0.17 ± 0.12 | M35: 1 | N35: 10.50 ± 3.01 | O35: 0.00 ± 0.00 | P35: 0.20 ± 0.17 | Q35: 1 | S35: blocks7 | T35: 29.60 ± 5.17 | U35: 12.84 ± 3.07 | V35: 0.52 ± 0.10 | W35: 1 | X35: 24.28 ± 1.70 | Y35: 0.00 ± 0.00 | Z35: 0.53 ± 0.05 | AA35: 1 | AB35: 17.00 ± 0.00 | AC35: 0.00 ± 0.00 | AD35: 0.41 ± 0.01 | AE35: 1 | AF35: 16.52 ± 0.50 | AG35: 0.00 ± 0.00 | AH35: 0.52 ± 0.05 | AI35: 1
A36: unix2 | B36: 185.42 ± 66.04 | C36: 149.80 ± 51.57 | D36: 4.41 ± 1.83 | E36: 1 | F36: 197.68 ± 68.42 | G36: 0.00 ± 0.00 | H36: 6.53 ± 2.20 | I36: 1 | J36: 88.36 ± 84.98 | K36: 0.00 ± 0.00 | L36: 2.60 ± 2.84 | M36: 1 | N36: 71.94 ± 65.67 | O36: 0.00 ± 0.00 | P36: 3.10 ± 3.67 | Q36: 1 | S36: unix2 | T36: 166.86 ± 72.07 | U36: 134.68 ± 56.37 | V36: 4.68 ± 2.37 | W36: 1 | X36: 191.80 ± 64.95 | Y36: 0.00 ± 0.00 | Z36: 7.47 ± 2.43 | AA36: 1 | AB36: 87.29 ± 79.17 | AC36: 0.00 ± 0.00 | AD36: 2.52 ± 2.85 | AE36: 1 | AF36: 60.84 ± 48.61 | AG36: 0.00 ± 0.00 | AH36: 2.31 ± 2.77 | AI36: 1
A37: unix3 | B37: 653.36 ± 313.81 | C37: 581.52 ± 277.10 | D37: 143.15 ± 99.22 | E37: 1 | F37: 749.72 ± 294.20 | G37: 0.00 ± 0.00 | H37: 262.53 ± 110.89 | I37: 1 | J37: 425.04 ± 385.62 | K37: 0.00 ± 0.00 | L37: 82.54 ± 78.64 | M37: 1 | N37: 268.68 ± 239.70 | O37: 0.00 ± 0.00 | P37: 78.44 ± 87.61 | Q37: 1 | S37: unix3 | T37: 641.08 ± 296.93 | U37: 572.88 ± 263.49 | V37: 174.30 ± 115.87 | W37: 1.00 | X37: 736.06 ± 282.71 | Y37: 0.00 ± 0.00 | Z37: 298.73 ± 123.03 | AA37: 1.00 | AB37: 360.23 ± 372.78 | AC37: 0.00 ± 0.00 | AD37: 86.96 ± 97.34 | AE37: 1.00 | AF37: 257.42 ± 260.81 | AG37: 0.00 ± 0.00 | AH37: 89.12 ± 116.40 | AI37: 1.00
A38: wumpus10 | B38: 91.67 ± 63.19 | C38: 37.00 ± 24.41 | D38: 3.57 ± 3.03 | E38: 1 | F38: 92.78 ± 63.24 | G38: 0.00 ± 0.00 | H38: 3.76 ± 2.71 | I38: 1 | J38: 50.40 ± 18.99 | K38: 0.00 ± 0.00 | L38: 1.20 ± 1.14 | M38: 1 | N38: 51.04 ± 21.20 | O38: 0.00 ± 0.00 | P38: 1.44 ± 1.85 | Q38: 0.9 | S38: wumpus10
A39: wumpus15 | B39: 181.33 ± 151.10 | C39: 77.87 ± 63.49 | D39: 32.05 ± 34.30 | E39: 1 | F39: 182.33 ± 151.10 | G39: 0.00 ± 0.00 | H39: 31.89 ± 28.78 | I39: 1 | J39: 74.67 ± 36.00 | K39: 0.00 ± 0.00 | L39: 9.84 ± 10.95 | M39: 1 | N39: 85.69 ± 53.12 | O39: 0.00 ± 0.00 | P39: 14.95 ± 22.88 | Q39: 1 | S39: wumpus15
A43: FB
A44: Problem | B44: Optimisitc | F44: Lazy | J44: MakeTrue
B45: Actions | C45: Failures | D45: Time | E45: SR | F45: Actions | G45: Failures | H45: Time | I45: SR | J45: Actions | K45: Failures | L45: Time | M45: SR
A46: doors-11 | B46: 92.06 ± 20.06 | C46: 2.06 ± 0.87 | D46: 1.17 ± 0.36 | E46: 1 | F46: 99.90 ± 25.10 | G46: 0.39 ± 0.53 | H46: 2.37 ± 0.72 | I46: 1 | J46: 83.31 ± 15.40 | K46: 0.53 ± 0.67 | L46: 3.48 ± 0.72 | M46: 0.98
A47: doors-13 | B47: 105.29 ± 25.07 | C47: 2.88 ± 1.15 | D47: 2.29 ± 0.77 | E47: 1 | F47: 107.55 ± 22.14 | G47: 0.65 ± 0.80 | H47: 3.96 ± 0.94 | I47: 1 | J47: 100.61 ± 26.47 | K47: 0.94 ± 0.91 | L47: 6.97 ± 2.19 | M47: 0.98
A48: doors-15 | B48: 165.73 ± 39.71 | C48: 3.08 ± 1.14 | D48: 6.25 ± 1.89 | E48: 1 | F48: 188.20 ± 38.19 | G48: 0.86 ± 0.88 | H48: 12.19 ± 3.03 | I48: 1 | J48: 142.84 ± 36.69 | K48: 0.76 ± 0.87 | L48: 17.85 ± 5.48 | M48: 0.98
A49: colorballs-9-3 | B49: 681.85 ± 184.12 | C49: 4.65 ± 1.62 | D49: 50.45 ± 17.35 | E49: 1 | F49: 689.59 ± 262.47 | G49: 1.06 ± 0.91 | H49: 51.48 ± 26.64 | I49: 1 | J49: 688.47 ± 261.85 | K49: 1.03 ± 0.86 | L49: 52.18 ± 26.11 | M49: 0.68
A50: colorballs-11-1 | B50: 460.55 ± 255.13 | C50: 1.21 ± 1.04 | D50: 72.15 ± 39.33 | E50: 1 | F50: 474.71 ± 236.76 | G50: 0.24 ± 0.48 | H50: 76.55 ± 41.19 | I50: 1 | J50: 397.71 ± 246.33 | K50: 0.29 ± 0.50 | L50: 63.03 ± 36.17 | M50: 0.84
...

Sheet domain stats
A1: problem | B1: init true | C1: init false
A2: unix1 | B2: 7 | C2: 49
A3: unix2 | B3: 15 | C3: 225
A4: unix3 | B4: 31 | C4: 961
A5: unix4 | B5: 63 | C5: 3969
A6: blocks3 | B6: 2 | C6: 7
A7: blocks7 | B7: 1 | C7: 44
A8: clog5 | B8: 4 | C8: 17
A9: clog7 | B9: 4 | C9: 17
A10: cloghuge | B10: 6 | C10: 124
A11: wumpus05 | B11: 1 | C11: 24
A12: wumpus10 | B12: 1 | C12: 99
A13: wumpus15 | B13: 1 | C13: 224
... A28: collorballs11-2 | B28: 4 | C28: 12

Sheet res
D6: FP | I6: FN | O6: FP - FN
D7: Problem | E7: Optimistic | F7: Pessimistic | G7: Lazy | I7: Problem | J7: Optimistic | K7: Pessimistic | L7: Lazy | M7: MakeTrue | O7: Problem | P7: Optimistic | Q7: Lazy - Lazy | R7: Lazy - MakeTrue
D8: doors-11 | I8: doors-11 | O8: doors-11
D9: doors-13 | I9: doors-13 | O9: doors-13
D10: doors-15 | I10: doors-15 | O10: doors-15
D11: colorballs-9-3 | I11: colorballs-9-3 | O11: colorballs-9-3
D12: colorballs-11-1 | I12: colorballs-11-1 | O12: colorballs-11-1
D13: colorballs-11-2 | I13: colorballs-11-2 | O13: colorballs-11-2
D14: cloghuge | I14: cloghuge | O14: cloghuge
D15: blocks7 | I15: blocks7 | O15: blocks7
D16: unix2 | I16: unix2 | O16: unix2
D17: unix3 | I17: unix3 | O17: unix3
D18: wumpus10 | I18: wumpus10 | O18: wumpus10
D19: wumpus15 | I19: wumpus15 | O19: wumpus15

Sheet results new format
D5: FP | S5: FP
D6: Problem | E6: Optimisitc | H6: Pessimistic | K6: Lazy | S6: Problem | T6: Optimisitc | V6: Pessimistic | X6: Lazy
E7: Actions | F7: Time | G7: % Success | H7: Actions | I7: Time | J7: % Success | K7: Actions | L7: Time | M7: % Success | T7: Actions | U7: Time | V7: Actions | W7: Time | X7: Actions | Y7: Time
D8: doors-11 | E8: 93.90 ± 24.13 | F8: 1.01 ± 0.38 | G8: 100 | H8: 135.08 ± 31.46 | I8: 2.96 ± 0.84 | J8: 100 | K8: 73.92 ± 13.91 | L8: 0.78 ± 0.21 | M8: 100 | S8: doors-11 | T8: 93.90 ± 24.13 | U8: 1.01 ± 0.38 | V8: 135.08 ± 31.46 | W8: 2.96 ± 0.84 | X8: 73.92 ± 13.91 | Y8: 0.78 ± 0.21
D9: doors-13 | E9: 108.90 ± 22.01 | F9: 1.80 ± 0.61 | G9: 100 | H9: 145.84 ± 28.70 | I9: 4.80 ± 1.14 | J9: 100 | K9: 84.96 ± 17.95 | L9: 1.38 ± 0.40 | M9: 100 | S9: doors-13 | T9: 108.90 ± 22.01 | U9: 1.80 ± 0.61 | V9: 145.84 ± 28.70 | W9: 4.80 ± 1.14 | X9: 84.96 ± 17.95 | Y9: 1.38 ± 0.40
D10: doors-15 | E10: 164.58 ± 34.05 | F10: 5.19 ± 1.59 | G10: 100 | H10: 239.30 ± 56.11 | I10: 15.39 ± 5.19 | J10: 100 | K10: 132.22 ± 26.81 | L10: 4.07 ± 1.11 | M10: 100 | S10: doors-15 | T10: 164.58 ± 34.05 | U10: 5.19 ± 1.59 | V10: 239.30 ± 56.11 | W10: 15.39 ± 5.19 | X10: 132.22 ± 26.81 | Y10: 4.07 ± 1.11
D11: colorballs-9-3 | E11: 711.46 ± 248.34 | F11: 67.57 ± 29.09 | G11: 100 | H11: 759.36 ± 219.35 | I11: 73.28 ± 26.07 | J11: 100 | K11: 704.66 ± 202.86 | L11: 64.68 ± 23.04 | M11: 100 | S11: colorballs-9-3 | T11: 711.46 ± 248.34 | U11: 67.57 ± 29.09 | V11: 759.36 ± 219.35 | W11: 73.28 ± 26.07 | X11: 704.66 ± 202.86 | Y11: 64.68 ± 23.04
D12: colorballs-11-1 | E12: 411.86 ± 232.55 | F12: 88.90 ± 50.97 | G12: 100 | H12: 541.48 ± 226.98 | I12: 126.75 ± 50.29 | J12: 100 | K12: 446.38 ± 247.33 | L12: 91.94 ± 53.42 | M12: 100 | S12: colorballs-11-1 | T12: 411.86 ± 232.55 | U12: 88.90 ± 50.97 | V12: 541.48 ± 226.98 | W12: 126.75 ± 50.29 | X12: 446.38 ± 247.33 | Y12: 91.94 ± 53.42
D13: colorballs-11-2 | E13: 822.10 ± 358.28 | F13: 205.88 ± 99.52 | G13: 100 | H13: 892.94 ± 396.07 | I13: 223.09 ± 102.63 | J13: 100 | K13: 914.72 ± 368.33 | L13: 211.08 ± 97.20 | M13: 100 | S13: colorballs-11-2 | T13: 822.10 ± 358.28 | U13: 205.88 ± 99.52 | V13: 892.94 ± 396.07 | W13: 223.09 ± 102.63 | X13: 914.72 ± 368.33 | Y13: 211.08 ± 97.20
D14: cloghuge | E14: 139.10 ± 13.01 | F14: 11.25 ± 2.02 | G14: 100 | H14: 155.08 ± 20.69 | I14: 20.87 ± 4.12 | J14: 100 | K14: 66.68 ± 9.31 | L14: 3.18 ± 0.85 | M14: 100 | S14: cloghuge | T14: 139.10 ± 13.01 | U14: 11.25 ± 2.02 | V14: 155.08 ± 20.69 | W14: 20.87 ± 4.12 | X14: 66.68 ± 9.31 | Y14: 3.18 ± 0.85
D15: blocks7 | E15: 27.68 ± 4.95 | F15: 0.39 ± 0.05 | G15: 100 | H15: 23.96 ± 1.73 | I15: 0.39 ± 0.05 | J15: 100 | K15: 11.24 ± 1.49 | L15: 0.14 ± 0.06 | M15: 100 | S15: blocks7 | T15: 27.68 ± 4.95 | U15: 0.39 ± 0.05 | V15: 23.96 ± 1.73 | W15: 0.39 ± 0.05 | X15: 11.24 ± 1.49 | Y15: 0.14 ± 0.06
D16: unix2 | E16: 178.40 ± 70.33 | F16: 4.55 ± 2.15 | G16: 100 | H16: 186.46 ± 72.11 | I16: 6.95 ± 2.83 | J16: 100 | K16: 45.72 ± 21.59 | L16: 0.45 ± 0.21 | M16: 100 | S16: unix2 | T16: 178.40 ± 70.33 | U16: 4.55 ± 2.15 | V16: 186.46 ± 72.11 | W16: 6.95 ± 2.83 | X16: 45.72 ± 21.59 | Y16: 0.45 ± 0.21
D17: unix3 | E17: 677.72 ± 250.11 | F17: 170.35 ± 94.60 | G17: 100 | H17: 696.46 ± 276.85 | I17: 278.06 ± 131.96 | J17: 100 | K17: 151.16 ± 71.90 | L17: 7.48 ± 3.75 | M17: 100 | S17: unix3 | T17: 677.72 ± 250.11 | U17: 170.35 ± 94.60 | V17: 696.46 ± 276.85 | W17: 278.06 ± 131.96 | X17: 151.16 ± 71.90 | Y17: 7.48 ± 3.75
D18: wumpus10 | E18: 111.70 ± 66.88 | F18: 5.08 ± 3.65 | G18: 100 | H18: 112.70 ± 66.88 | I18: 5.92 ± 4.06 | J18: 100 | K18: 65.84 ± 20.49 | L18: 1.64 ± 0.58 | M18: 100 | S18: wumpus10 | T18: 111.70 ± 66.88 | U18: 5.08 ± 3.65 | V18: 112.70 ± 66.88 | W18: 5.92 ± 4.06 | X18: 65.84 ± 20.49 | Y18: 1.64 ± 0.58
D19: wumpus15 | E19: 177.48 ± 139.71 | F19: 34.90 ± 34.95 | G19: 100 | H19: 178.48 ± 139.71 | I19: 44.08 ± 40.79 | J19: 100 | K19: 127.96 ± 41.49 | L19: 16.24 ± 5.89 | M19: 100 | S19: wumpus15 | T19: 177.48 ± 139.71 | U19: 34.90 ± 34.95 | V19: 178.48 ± 139.71 | W19: 44.08 ± 40.79 | X19: 127.96 ± 41.49 | Y19: 16.24 ± 5.89
D23: FN | Q23: duplicate table
D24: Problem | E24: Optimisitc | H24: Pessimistic | K24: Lazy | N24: MakeTrue | Q24: only if deadend
E25: Actions | F25: Time | G25: % Success | H25: Actions | I25: Time | J25: % Success | K25: Actions | L25: Time | M25: % Success | N25: Actions | O25: Time | P25: % Success
D26: doors-11 | E26: 94.34 ± 18.77 | F26: 0.74 ± 0.21 | G26: 100 | H26: 138.92 ± 27.72 | I26: 2.11 ± 0.47 | J26: 100 | K26: 97.12 ± 23.34 | L26: 1.21 ± 0.37 | M26: 100 | N26: 66.00 ± 16.88 | O26: 0.86 ± 0.30 | P26: 8
D27: doors-13 | E27: 107.62 ± 23.35 | F27: 1.43 ± 0.45 | G27: 100 | H27: 144.96 ± 26.76 | I27: 3.80 ± 0.74 | J27: 100 | K27: 104.50 ± 21.32 | L27: 2.25 ± 0.64 | M27: 100 | N27: 57.50 ± 7.50 | O27: 0.80 ± 0.14 | P27: 4
D28: doors-15 | E28: 164.50 ± 31.83 | F28: 3.75 ± 1.07 | G28: 100 | H28: 251.20 ± 47.49 | I28: 11.32 ± 3.54 | J28: 100 | K28: 177.50 ± 45.41 | L28: 6.16 ± 2.23 | M28: 100 | N28: 150.50 ± 22.50 | O28: 5.14 ± 0.49 | P28: 4
D29: colorballs-9-3 | E29: 694.56 ± 201.67 | F29: 53.93 ± 21.16 | G29: 100 | H29: 770.56 ± 228.24 | I29: 59.28 ± 22.16 | J29: 100 | K29: 736.46 ± 183.48 | L29: 55.72 ± 17.82 | M29: 100 | N29: 758.64 ± 227.02 | O29: 60.57 ± 30.70 | P29: 72
D30: colorballs-11-1 | E30: 454.60 ± 252.97 | F30: 72.59 ± 41.06 | G30: 100 | H30: 500.48 ± 280.64 | I30: 84.38 ± 44.97 | J30: 100 | K30: 475.96 ± 250.24 | L30: 77.44 ± 43.31 | M30: 100 | N30: 473.39 ± 234.21 | O30: 74.69 ± 40.16 | P30: 76
D31: colorballs-11-2 | E31: 858.92 ± 353.10 | F31: 156.49 ± 71.00 | G31: 100 | H31: 912.36 ± 403.46 | I31: 167.42 ± 77.67 | J31: 100 | K31: 872.92 ± 313.12 | L31: 160.38 ± 65.93 | M31: 100 | N31: 874.37 ± 328.26 | O31: 165.50 ± 73.40 | P31: 70
